Workbook

Sheet Contract
A1: SALES CONTRACT
D3: DATE: | E3: =Invoice!G9 -> 46028
D4: CONTRACT NO.: | E4: =Invoice!G8 -> JF26001
A5: The Seller: | B5: CALIFOR UPHOLSTERY MATERIALS CO.,LTD.
B6: XIN BAVET SEZ, Road No. 316A, Trapeang Bon and Prey Kokir Villages, Prey Kokir Commune, Chantrea District,
B7: Svay Rieng Province, Kingdom of Cambodia.
A8: TEL: | B8: +855 975910636
A9: The Buyer: | B9: JASON FURNITURE VIET NAM COMPANY LIMITED
B10: LOT 37, 38, 39, 40, 41, 44, 50, 51, 54，55, 56，B2 CLUSTER, DONG XOAI III INDUSTRIAL PARK,
B11: BINH PHUOC WARD, DONG NAI PROVINCE, VIETNAM
A12: Contact Person : Contact Person : Mr. Thuy Tel: 0379367084
A13: EMAll:jyangbin4720@dingtalk.com jialy@kukahome.com dailin@kukahome.com huanggf@kukahome.com zhangzp@kukahome.com
A14: The undersigned Sellers 、Buyers and Beneficiary have agreed to close the following transactions according to the terms and conditions Stipulated below:
A15: No. | B15: ITEM Nº | C15: Quantity(SF) | D15: Unit Price(USD) | E15: Total value(USD)
A16: 1 | B16: 01.10.U243082/01.10.U741030 01.10.U756090/01.10.U528073 01.10.U528103/01.10.W783032 01.10.W782023/01.10.W783010-K 01.10.O6508/01.10.W782011 01.10.U756022/ | C16: 205429.4 | D16: =E16/C16 -> 1.3265683 | E16: 272516.14
A17: 2 | B17: 01.11.S756022 | C17: 3851.2 | D17: =E17/C17 -> 0.88 | E17: 3389.056
A18: TOTAL: | C18: =SUM(C16:C17) -> 209280.6 | E18: =SUM(E16:E17) -> 275905.19
A20: DAF: | B20: BAVET
A21: Term of Payment: 100% TT after shipment
A22: Transaction method: DAF(USD)
A23: Beneficiary bank information: | C23: CALIFOR UPHOLSTERY MATERIALS CO.,LTD.
A24: Beneficiary Bank' s Name: | C24: BANK OF CHINA(HONG KONG)LIMITED PHNOM PENH BRANCH /BANK OF CHINA PHNOM PENH BRANCH
A25: Bank Address: | C25: 1st AND 2nd FLOOR,CANADIA TOWER,No.315 ANDDUONG ST. PHNOM PEMH,CAMBODIA.
A26: Bank account : | C26: 100001100764430
A27: SWIFT CODE ： | C27: BKCHKHPPXXX
A29: The Buyer: | D29: The Seller:
A30: JASON FURNITURE VIET NAM COMPANY LIMITED | D30: CALIFOR UPHOLSTERY MATERIALS CO.,LTD.

Sheet Invoice
A1: CALIFOR UPHOLSTERY MATERIALS CO., LTD.
A2: XIN BAVET SEZ, Road No. 316A, Trapeang Bon and Prey Kokir Villages, Prey Kokir Commune, Chantrea District,
A3: Svay Rieng Province, Kingdom of Cambodia.
A4: VAT:L001-901903209
A5: Tel: +855 975910636
A6: INVOICE
F7: Ref No.: | G7: ='Packing list'!I7 -> CLF2026-009
A8: EXPORTER: | B8: CALIFOR UPHOLSTERY MATERIALS CO., LTD. | F8: INVOICE NO : | G8: ='Packing list'!I8 -> JF26001
B9: XIN BAVET SEZ, Road No. 316A, Trapeang Bon and Prey Kokir Villages, | F9: Date: | G9: ='Packing list'!I9 -> 46028
B10: Prey Kokir Commune, Chantrea District,Svay Rieng Province, Kingdom of Cambodia | F10: ='Packing list'!H10 -> DAF : | G10: ='Packing list'!I10 -> BAVET
B11: Tel: +855 975910636
A13: CONSIGNEE : | B13: JASON FURNITURE VIET NAM COMPANY LIMITED
B14: LOT 37, 38, 39, 40, 41, 44, 50, 51, 54，55, 56，B2 CLUSTER, DONG XOAI III INDUSTRIAL PARK,
B15: BINH PHUOC WARD,DONG NAI PROVINCE, VIETNAM
B16: Contact Person : Mr. Thuy TEl: 0379367084
B17: EMAlL:jyangbin4720@dingtalk.com jialy@kukahome.com
B18: dailin@kukahome.com huanggf@kukahome.com zhangzp@kukahome.com
A19: SHIP: | B19: BY TRUCK FROM BAVET, SVAY RIENG, CAMBODIA TO DONG NAI PROVINCE, VIETNAM.
A21: Mark & Nº | B21: P.O. Nº | C21: ITEM Nº | D21: Description | E21: Quantity(SF) | F21: Unit price (USD) | G21: Amount (USD)
A22: VENDOR#: | B22: 9000824229/9000835028/9000862772 9000869348/9000869831/9000870684 9000870701/9000872902 | C22: 01.10.U243082/01.10.U741030 01.10.U756090/01.10.U528073 01.10.U528103/01.10.W783032 01.10.W782023/01.10.W783010-K 01.10.O6508/01.10.W782011 01.10.U756022/ | D22: COW LEATHER | E22: 205429.4 | F22: =G22/E22 -> 1.3265683 | G22: 272516.14
A23: Des: COW LEATHER | B23: 9000872902 | C23: 01.11.S756022 | E23: 3851.2 | F23: =G23/E23 -> 0.88 | G23: 3389.056
A24: MADE IN CAMBODIA
B25: TOTAL: | C25: 29 PALLETS | E25: =SUM(E22:E24) -> 209280.6 | G25: =SUM(G22:G24) -> 275905.19
A27: Country of Original Cambodia
A28: Manufacture: | B28: CALIFOR UPHOLSTERY MATERIALS CO., LTD. XIN BAVET SEZ, Road No. 316A, Trapeang Bon and Prey Kokir Villages, Prey Kokir Commune, Chantrea District,Svay Rieng Province, Kingdom of Cambodia, Tel: +855 975910636
A29: BENEFICIARY BANK：BANK OF CHINA(HONG KONG)LIMITED PHNOM PENH BRANCH /BANK OF CHINA PHNOM PENH BRANCH
A30: A/C NO:100001100764430
A31: SWIFT CODE ：BKCHKHPPXXX
E32: CALIFOR UPHOLSTERY MATERIALS CO., LTD.
F33: Sign & Stamp
F39: ZENG XUELI

Sheet Packing list
A1: CALIFOR UPHOLSTERY MATERIALS CO., LTD.
A2: XIN BAVET SEZ, Road No. 316A, Trapeang Bon and Prey Kokir Villages, Prey Kokir Commune, Chantrea District,
A3: Svay Rieng Province, Kingdom of Cambodia.
A4: VAT:L001-901903209
A5: Tel: +855 975910636
A6: PACKING LIST
H7: Ref No.: | I7: CLF2026-009
A8: EXPORTER: | B8: CALIFOR UPHOLSTERY MATERIALS CO., LTD. | H8: INVOICE NO : | I8: JF26001
B9: XIN BAVET SEZ, Road No. 316A, Trapeang Bon and Prey Kokir Villages, | H9: Date: | I9: 46028
B10: Prey Kokir Commune, Chantrea District,Svay Rieng Province, Kingdom of Cambodia | H10: DAF : | I10: BAVET
B11: Tel: +855 975910636
A13: CONSIGNEE : | B13: JASON FURNITURE VIET NAM COMPANY LIMITED
B14: LOT 37, 38, 39, 40, 41, 44, 50, 51, 54，55, 56，B2 CLUSTER, DONG XOAI III INDUSTRIAL PARK,
B15: BINH PHUOC WARD, DONG NAI PROVINCE, VIETNAM
B16: Contact Person : Mr. Thuy TEl: 0379367084
B17: EMAlL:jyangbin4720@dingtalk.com jialy@kukahome.com
B18: dailin@kukahome.com huanggf@kukahome.com zhangzp@kukahome.com
A19: SHIP: | B19: BY TRUCK FROM BAVET, SVAY RIENG, CAMBODIA TO DONG NAI PROVINCE, VIETNAM.
A21: Mark & Nº | B21: P.O Nº | C21: ITEM Nº | D21: Description | E21: Quantity(SF) | G21: N.W (kgs) | H21: G.W (kgs) | I21: CBM
E22: PCS | F22: SF
A23: VENDOR#: | B23: 9000870701 | C23: 01.10.W783032 | D23: COW LEATHER | E23: 121 | F23: 6382.7 | G23: 631 | H23: 676 | I23: 2.3364
A24: Des: COW LEATHER | B24: 9000870701 | C24: 01.10.W783032 | E24: 125 | F24: 6852.5 | G24: 671.02713 | H24: 714.63178 | I24: 2.4174419
A25: Case Qty: | B25: 9000870701 | C25: 01.10.W783032 | E25: 4 | F25: 154 | G25: 21.472868 | H25: 22.868217 | I25: 0.07735814
A26: MADE IN CAMBODIA | B26: 9000870684 | C26: 01.10.W783010-K | E26: 180 | F26: 9002.3 | G26: 690.67873 | H26: 727.33032 | I26: 2.0319638
B27: 9000870684 | C27: 01.10.W783010-K | E27: 41 | F27: 1610.8 | G27: 157.32127 | H27: 165.66968 | I27: 0.4628362
B28: 9000870684 | C28: 01.10.W783010-K | E28: 200 | F28: 10126.1 | G28: 813 | H28: 858 | I28: 2.5344
B29: 9000870684 | C29: 01.10.W783010-K | E29: 170 | F29: 8444.4 | G29: 627.9375 | H29: 659.8125 | I29: 2.0196
B30: 9000870684 | C30: 01.10.W783010-K | E30: 70 | F30: 2706.1 | G30: 258.5625 | H30: 271.6875 | I30: 0.8316
B31: 9000870684 | C31: 01.10.W783010-K | E31: 92 | F31: 4580.7 | G31: 341.05714 | H31: 370.62857 | I31: 1.2490971
B32: 9000870684 | C32: 01.10.W783010-K | E32: 35 | F32: 1351.9 | G32: 129.75 | H32: 141 | I32: 0.4752
B33: 9000870684 | C33: 01.10.W783010-K | E33: 13 | F33: 535.6 | G33: 48.192857 | H33: 52.371429 | I33: 0.17650286
B34: 9000862772 | C34: 01.10.U756090 | E34: 130 | F34: 6294.7 | G34: 505.2454 | H34: 541.13497 | I34: 1.768638
B35: 9000862772 | C35: 01.10.U756090 | E35: 17 | F35: 667.9 | G35: 66.070552 | H35: 70.763804 | I35: 0.23128344
B36: 9000862772 | C36: 01.10.U756090 | E36: 16 | F36: 709.3 | G36: 62.184049 | H36: 66.601227 | I36: 0.21767853
B37: 9000862772 | C37: 01.10.U756090 | E37: 113 | F37: 5491.9 | G37: 442.36434 | H37: 481.78295 | I37: 1.9425488
B38: 9000862772 | C38: 01.10.U756090 | E38: 16 | F38: 626.7 | G38: 62.635659 | H38: 68.217054 | I38: 0.27505116
... B64: 9000872902 | C64: 01.10.W783010-K | E64: 112 | F64: 471.3 | G64: 46.23913 | H64: 52.108696 | I64: 0.2066087
B65: TOTAL: | C65: 23 PALLETS | E65: =SUM(E23:E64) -> 3458 | F65: =SUM(F23:F64) -> 164623.5 | G65: =SUM(G23:G64) -> 14506 | H65: =SUM(H23:H64) -> 15541 | I65: =SUM(I23:I64) -> 49.6584
A67: Mark & Nº | B67: P.O Nº | C67: ITEM Nº | D67: Description | E67: Quantity(SF) | G67: N.W (kgs) | H67: G.W (kgs) | I67: CBM
E68: PCS | F68: SF
...
